// what is the output? and explain why?

// 1
// 1, catch and the afterwards won't be called
Promise.resolve(1)
  .then(res => {
    console.log(res);
    return 2;
  })
  .catch(err => {
    return 3;
  })
  .then(res => {
    console.log(res);
  });

// // 2
// 1 > 3
// the first then will be skipped because of the reject
Promise.reject(1)
  .then(res => {
    console.log(res);
    return 2;
  })
  .catch(err => {
    console.log(err);
    return 3;
  })
  .then(res => {
    console.log(res);
  });

//3
// Error: 2
// Promise.all will wait for all done or one of them reject, the first reject will happen at 2 second
function runAsync(x) {
  const p = new Promise(resolve =>
    setTimeout(() => resolve(x), 1000)
  );
  return p;
}

function runReject(x) {
  const p = new Promise((resolve, reject) =>
    setTimeout(() => reject(`Error: ${x}`), 1000 * x)
  );
  return p;
}

Promise.all([runAsync(1), runReject(4), runAsync(3), runReject(2)])
  .then(res => console.log(res))
  .catch(err => console.log(err));
